<?xml version="1.0"?>
<robot xmlns:xacro="http://www.ros.org/wiki/xacro" >

    <xacro:include filename="inertial_macros.xacro" />
    <material name="white">
        <color rgba="1 1 1 1" />
    </material>

    <material name="orange">
        <color rgba="1 0.3 0.1 1"/>
    </material>

    <material name="blue">
        <color rgba="0.2 0.2 1 1"/>
    </material>

    <material name="black">
        <color rgba="0 0 0 1"/>
    </material>

    <material name="red">
        <color rgba="1 0 0 1"/>
    </material>

    <!-- BASE LINK -->

    <link name="base_link">

    </link>

    <joint name="chassis_joint" type="fixed">
        <parent link="base_link"/>
        <child link="chassis"/>
        <origin xyz="0 0 0"/>
    </joint>
    
    <link name="chassis">
        <visual>
            <origin xyz="0.225 0.3 0" rpy="0 0 -${pi}"/>
            <geometry>
                <mesh filename="file:///home/turborocket/turbofinal_ws/src/articubot_one/description/testbody2.dae"/>
            </geometry>
            <material name="white"/>
        </visual>
        <collision>
                <origin xyz="0.225 0.3 0" rpy="0 0 -${pi}"/>
            <geometry>
                <mesh filename="file:///home/turborocket/turbofinal_ws/src/articubot_one/description/testbody2.dae"/>
            </geometry>
        </collision>
        <xacro:inertial_box mass="20" x="0.2" y="0.3" z="0.15">
            <origin xyz="0 0 0.06" rpy="0 0 0"/>
        </xacro:inertial_box>
    </link>
    <gazebo reference="chassis">
        <material>Gazebo/White</material>
    </gazebo>

    <!-- LEFT TOP WHEEL -->

    <joint name="left_wheel_joint" type="continuous">
        <parent link="base_link"/>
        <child link="left_wheel"/>
        <origin xyz="0.15 0.09 0.03" rpy="0 0 0"/>
        <axis xyz="-1 0 0"/>
    </joint>
    <link name="left_wheel">
    <visual>
        <origin xyz="0 0 0" rpy="0 0 0"/>
        <geometry>
            <mesh filename="file:///home/turborocket/turbofinal_ws/src/articubot_one/description/testwheel2.dae"/>
        </geometry>
        <material name="blue"/>
    </visual>
    <collision>
        <origin xyz="0 0 0" rpy="0 0 0"/>
        <geometry>
            <mesh filename="file:///home/turborocket/turbofinal_ws/src/articubot_one/description/testwheel2.dae"/>
        </geometry>
    </collision>
    <xacro:inertial_cylinder mass="10" length="0.05" radius="0.09">
        <origin xyz="0.04 0 0" rpy="0 ${pi/2} 0"/>
    </xacro:inertial_cylinder>
    </link>
    <gazebo reference="left_wheel">
        <material>Gazebo/black</material>
    </gazebo>


    <!-- LEFT LOWER WHEEL -->

    <joint name="left_wheel_joint2" type="continuous">
        <parent link="base_link"/>
        <child link="left_wheel2"/>
        <origin xyz="0.15 -0.15 0.03" rpy="0 0 0"/>
        <axis xyz="-1 0 0"/>
    </joint>
    <link name="left_wheel2">
    <visual>
        <origin xyz="0 0 0" rpy="0 0 0"/>
        <geometry>
            <mesh filename="file:///home/turborocket/turbofinal_ws/src/articubot_one/description/testwheel2.dae"/>
        </geometry>
        <material name="blue"/>
    </visual>
    <collision>
        <origin xyz="0 0 0" rpy="0 0 0"/>
        <geometry>
            <mesh filename="file:///home/turborocket/turbofinal_ws/src/articubot_one/description/testwheel2.dae"/>
        </geometry>
    </collision>
    <xacro:inertial_cylinder mass="10" length="0.05" radius="0.09">
        <origin xyz="0.04 0 0" rpy="0 ${pi/2} 0"/>
    </xacro:inertial_cylinder>
    </link>
    <gazebo reference="left_wheel2">
        <material>Gazebo/black</material>
    </gazebo>

        <!-- RIGHT TOP WHEEL -->

    <joint name="right_wheel_joint" type="continuous">
        <parent link="base_link"/>
        <child link="right_wheel"/>
        <origin xyz="-0.15 0.09 0.03" rpy="0 -${pi} 0"/>
        <axis xyz="1 0 0"/>
    </joint>

    <link name="right_wheel">
        <visual>
            <origin xyz="0 0 0" rpy="0 0 0"/>
            <geometry>
                <mesh filename="file:///home/turborocket/turbofinal_ws/src/articubot_one/description/testwheel2.dae"/>
            </geometry>
            <material name="blue"/>
        </visual>
        <collision>
            <origin xyz="0 0 0" rpy="0 0 0"/>
            <geometry>
                <mesh filename="file:///home/turborocket/turbofinal_ws/src/articubot_one/description/testwheel2.dae"/>
            </geometry>
        </collision>
        <xacro:inertial_cylinder mass="10" length="0.05" radius="0.09">
            <origin xyz="0.04 0 0" rpy="0 ${pi/2} 0"/>
        </xacro:inertial_cylinder>
    </link>
    <gazebo reference="right_wheel">
        <material>Gazebo/black</material>
    </gazebo>

    <!-- RIGHT LOWER WHEEL -->

    <joint name="right_wheel_joint2" type="continuous">
        <parent link="base_link"/>
        <child link="right_wheel2"/>
        <origin xyz="-0.15 -0.15 0.03" rpy="0 -${pi} 0"/>
        <axis xyz="1 0 0"/>
    </joint>

    <link name="right_wheel2">
        <visual>
        <origin xyz="0 0 0" rpy="0 0 0"/>
            <geometry>
                <mesh filename="file:///home/turborocket/turbofinal_ws/src/articubot_one/description/testwheel2.dae"/>
            </geometry>
            <material name="blue"/>
        </visual>
        <collision>
            <origin xyz="0 0 0" rpy="0 0 0"/>
            <geometry>
                <mesh filename="file:///home/turborocket/turbofinal_ws/src/articubot_one/description/testwheel2.dae"/>
            </geometry>
        </collision>
        <xacro:inertial_cylinder mass="10" length="0.05" radius="0.09">
            <origin xyz="0.04 0 0" rpy="0 ${pi/2} 0"/>
        </xacro:inertial_cylinder>
    </link>
    <gazebo reference="right_wheel2">
        <material>Gazebo/black</material>
    </gazebo>
   <!-- SCOOPER ARM -->

    <joint name="scooper_joint" type="revolute">
        <limit effort="1000.0" lower="1.54" upper="3" velocity="0.5"/>
        <parent link="base_link"/>
        <child link="scooper"/>
        <origin xyz="0.1 -0.1 0.25" rpy="0 ${pi} 0"/>
        <axis xyz="-1 0 0"/>
        <dynamics damping="1" friction="1"/>
    </joint>
    <link name="scooper">
    <visual>
        <origin xyz="0 0 0" rpy="0 0 0"/>
        <geometry>
            <mesh filename="file:///home/turborocket/turbofinal_ws/src/articubot_one/description/newscoober3.dae"/>
        </geometry>
        <material name="blue"/>
    </visual>
    <collision>
        <origin xyz="0 0 0" rpy="0 0 0"/>
        <geometry>
            <mesh filename="file:///home/turborocket/turbofinal_ws/src/articubot_one/description/newscoober3.dae"/>
        </geometry>
    </collision>
    <xacro:inertial_cylinder mass="10" length="0.05" radius="0.05">
        <origin xyz="0 0 0" rpy="0 ${pi/2} 0"/>
    </xacro:inertial_cylinder>
    </link>
    <gazebo reference="scooper">
        <material>Gazebo/blue</material>
    </gazebo>

    <!-- HELPER LEFT ARM -->

    <joint name="helperleft_joint" type="revolute">
        <limit effort="1000.0" lower="0" upper="20" velocity="0.5"/>
        <parent link="base_link"/>
        <child link="helper_left"/>
        <origin xyz="-0.225 0.25 0.1" rpy="${pi} ${pi} 0"/>
        <axis xyz="1 0 0"/>
        <dynamics damping="1" friction="1"/>
    </joint>
    <link name="helper_left">
    <visual>
        <origin xyz="0 0 0" rpy="0 0 0"/>
        <geometry>
            <mesh filename="file:///home/turborocket/turbofinal_ws/src/articubot_one/description/testhelperarm.dae"/>
        </geometry>
        <material name="blue"/>
    </visual>
    <collision>
        <origin xyz="0 0 0" rpy="0 0 0"/>
        <geometry>
            <mesh filename="file:///home/turborocket/turbofinal_ws/src/articubot_one/description/testhelperarm.dae"/>
        </geometry>
    </collision>
    <xacro:inertial_cylinder mass="10" length="0.05" radius="0.05">
        <origin xyz="0 0 0" rpy="0 ${pi/2} 0"/>
    </xacro:inertial_cylinder>
    </link>
    <gazebo reference="helper_left">
        <material>Gazebo/orange</material>
    </gazebo>

    <!-- HELPER RIGHT ARM -->

    <joint name="helperright_joint" type="revolute">
        <limit effort="1000.0" lower="0" upper="20" velocity="0.5"/>
        <parent link="base_link"/>
        <child link="helper_right"/>
        <origin xyz="0.225 0.25 0.1" rpy="0 0 0"/>
        <axis xyz="-1 0 0"/>
        <dynamics damping="1" friction="1"/>
    </joint>
    <link name="helper_right">
    <visual>
        <origin xyz="0 0 0" rpy="0 0 0"/>
        <geometry>
            <mesh filename="file:///home/turborocket/turbofinal_ws/src/articubot_one/description/testhelperarm.dae"/>
        </geometry>
        <material name="blue"/>
    </visual>
    <collision>
        <origin xyz="0 0 0" rpy="0 0 0"/>
        <geometry>
            <mesh filename="file:///home/turborocket/turbofinal_ws/src/articubot_one/description/testhelperarm.dae"/>
        </geometry>
    </collision>
    <xacro:inertial_cylinder mass="10" length="0.05" radius="0.05">
        <origin xyz="0 0 0" rpy="0 ${pi/2} 0"/>
    </xacro:inertial_cylinder>
    </link>
    <gazebo reference="helper_right">
        <material>Gazebo/orange</material>
    </gazebo>
</robot>